#VRML_SIM R2019a utf8
WorldInfo {
}
Viewpoint {
  orientation -0.2146633162075385 0.953340693436622 0.2122761948796028 1.5782870365307449
  position 1.27424445004304 0.8344901007043675 0.0682055076091137
}
TexturedBackground {
}
TexturedBackgroundLight {
}
Floor {
}
Robot {
  translation 0 0.15 0
  children [
    Shape {
      appearance PBRAppearance {
        baseColor 0.5411764705882353 0.8862745098039215 0.20392156862745098
      }
      geometry Box {
        size 0.1 0.3 0.1
      }
    }
    HingeJoint {
      jointParameters HingeJointParameters {
        axis 0 1 0
        anchor 0 0.15 0
      }
      device [
        RotationalMotor {
          name "servo_motor"
          maxVelocity 13.1
          maxTorque 0.216
        }
      ]
      endPoint Solid {
        translation 0 0.2 0
        children [
          DEF G_RED_BOX Shape {
            appearance PBRAppearance {
              baseColor 0.9372549019607843 0.1607843137254902 0.1607843137254902
            }
            geometry Box {
              size 0.1 0.1 0.1
            }
          }
          HingeJoint {
            jointParameters HingeJointParameters {
              position 1
              axis 0 1 0
              anchor 0 0.15 0
              minStop 1
              maxStop 1
              springConstant 0.1
              dampingConstant 0.1
            }
            device [
              RotationalMotor {
                name "servo_motor2"
                maxVelocity 13.1
                maxTorque 0.216
              }
            ]
            endPoint Solid {
              translation 0 0.1 0
              rotation 0 1 0 5.151070676509251
              children [
                DEF D_box2 Shape {
                  appearance PBRAppearance {
                  }
                  geometry Box {
                    size 0.1 0.1 0.1
                  }
                }
                HingeJoint {
                  jointParameters HingeJointParameters {
                    position -1
                    axis 0 0 1
                    anchor 0 0.1 0
                    minStop -1
                    maxStop 0.5
                    springConstant 0.01
                    dampingConstant 1
                  }
                  device [
                    RotationalMotor {
                      name "servo_motor3"
                      maxVelocity 12.6
                      minPosition -1.5
                      maxPosition 50
                      maxTorque 0.256
                    }
                  ]
                  endPoint Solid {
                    translation -1.3877787807814457e-17 0.15 0
                    rotation 0 0 1 0
                    children [
                      DEF D_arm3 Shape {
                        appearance PBRAppearance {
                          baseColor 0.9372549019607843 0.1607843137254902 0.1607843137254902
                        }
                        geometry Capsule {
                          height 0.1
                          radius 0.05
                        }
                      }
                    ]
                    boundingObject USE D_arm3
                    physics Physics {
                    }
                  }
                }
              ]
              name "arm2"
              boundingObject USE D_box2
              physics Physics {
              }
              rotationStep 0
            }
          }
        ]
        boundingObject USE G_RED_BOX
        physics Physics {
        }
      }
    }
  ]
  controller "Robot2"
}
